Workbook
Name BOSDubai: Tracker!$C$9:$C$122

Sheet Tracker
AB1: EXPECTED SAVINGS NEW VERSION | AM1: EXPECTED SAVINGS OLD VERSION
B2: This is the Vessel Installation Tracker Sheet. | E2: EACH VESSEL : WHAT TO DO ? | K2: If any issues concerning the Excel Sheet Please refer to Axel FAURAX | N2: 2000 year | O2: ton MGO | Q2: =2000*0.01 -> 20 | T2: To remind : | U2: MGPS : All existing vessels IWTM Filter : Whole fleet + new assets Lightning System CMCE : All DP 2 vessels which are used as DP2 if vessel is not used as DP2 then it is not required MGPS + Chlorinator : New assets | AB2: Device | AC2: Scope 1 | AD2: Scope 3 | AE2: Co2 savings ton/year | AF2: FOR FACTOR 1 | AM2: Devices (for 100tonnage) | AN2: Scope 1 | AO2: Scope 3 | AP2: Co2 savings ton/year | AQ2: FOR FACTOR 1
N3: MGO | O3: 3.2 | Q3: =O3*Q2 -> 64 | AB3: MGPS | AC3: 11000 | AD3: 3200 | AE3: 64 | AF3: 1 | AM3: MGPS | AN3: 11000 | AO3: 3200 | AP3: 64 | AQ3: 1
B4: To remind : | C4: I would like all vessels to do go and check the status. Here we report all the installation of the new initiatives we put onto the whole fleet | E4: Please scroll down to your vessel name. You will see all the devices we need to track | F4: Please select on "Installation Status" when clicking into the cell, one of the statement written. | H4: If possible, Please fill the chief engineer name and the installation date | N4: price mgo | O4: 600 | P4: usd | R4: =8000/25 -> 320 | AB4: Chlorinator | AC4: 15000 | AD4: 3200 | AE4: =INT($AE$3*AC4/$AC$3) -> 87 | AF4: 1 | AM4: Chlorinator | AN4: 0 | AO4: 3200 | AP4: 50 | AQ4: 1
AB5: CMCE LP | AC5: 0 | AD5: 500 | AE5: =INT($AE$3*AC5/$AC$3) -> 0 | AF5: 1 | AM5: CMCE LP | AN5: 0 | AO5: 500 | AP5: 0 | AQ5: 1
AB6: CJC Filter | AC6: 2500 | AD6: 5000 | AE6: =INT($AE$3*AC6/$AC$3) -> 14 | AF6: 1 | AM6: IWTM Filter | AN6: 2500 | AO6: 3200 | AP6: 11 | AQ6: 1
M7: Custom ligne (a) | AB7: IWTM Filter | AC7: 1500 | AD7: =3200+3000 -> 6200 | AE7: =INT($AE$3*AC7/$AC$3) -> 8 | AF7: 1 | AM7: LED lights | AN7: 8300 | AO7: 1000 | AP7: 45 | AQ7: 1
B8: N | C8: Vessel Name/ ID | D8: Spec | E8: Devices | F8: Installation Status | G8: Date of Installation | H8: Scope 1 Expected Savings/year | I8: Scope 3 Expected Savings/year | J8: Co2 savings ton/year | K8: Chief Engineer Name | L8: Comments/Remarks | U8: help column | V8: factor | W8: old value of Fuel cons fuel power | Y8: fuel cons 24hours full power literse | AB8: LED lights | AC8: 8300 | AD8: 4000 | AE8: 85 | AF8: 1 | AM8: EFMS Ascenz GEN E KIT | AN8: 16000 | AO8: 2000 | AP8: 85 | AQ8: 1
A9: a | B9: 1 | C9: Britoil 21 | D9: AHT E | E9: ↓ | H9: =IF(F9="Done", V9*VLOOKUP(E9, $AB$3:$AC$16, 2, FALSE), "") | I9: =IF(F9="Done", V9*VLOOKUP(E9, $AB$3:$AD$16, 3, FALSE), "") | J9: =IF(F9="Done", V9*VLOOKUP(E9, $AB$3:$AE$16, 4, FALSE), "") | U9: =C9 -> Britoil 21 | V9: =MIN(Y9/21388,1.3) -> 0.51430709 | W9: =VLOOKUP(U9, $AB$30:$AH$96, 7, FALSE) -> 11000 | Y9: =INT(VLOOKUP(U9, $AB$30:$AH$101, 7, FALSE)) -> 11000 | AB9: EFMS | AC9: 16000 | AD9: 1000 | AE9: =INT($AE$3*AC9/$AC$3) -> 93 | AF9: 1 | AM9: EFMS | AN9: 8000 | AO9: 1000 | AP9: 40 | AQ9: 1
E10: LED lights | F10: Not Installed | H10: =IF(F10="Done", V10*VLOOKUP(E10, $AB$3:$AC$16, 2, FALSE), "") | I10: =IF(F10="Done", V10*VLOOKUP(E10, $AB$3:$AD$16, 3, FALSE), "") | J10: =IF(F10="Done", V10*VLOOKUP(E10, $AB$3:$AE$16, 4, FALSE), "") | U10: Britoil 21 | V10: =MIN(Y10/21388,1.3) -> 0.51430709 | W10: 11000 | Y10: =INT(VLOOKUP(U10, $AB$30:$AH$101, 7, FALSE)) -> 11000 | AB10: Deva Paint | AC10: 0 | AD10: 4000 | AE10: 30 | AF10: 1 | AM10: AI CCTV | AN10: 0 | AO10: 4000 | AP10: 0 | AQ10: 1
E11: EFMS | F11: Not Installed | H11: =IF(F11="Done", V11*VLOOKUP(E11, $AB$3:$AC$16, 2, FALSE), "") | I11: =IF(F11="Done", V11*VLOOKUP(E11, $AB$3:$AD$16, 3, FALSE), "") | J11: =IF(F11="Done", V11*VLOOKUP(E11, $AB$3:$AE$16, 4, FALSE), "") | U11: Britoil 21 | V11: =MIN(Y11/21388,1.3) -> 0.51430709 | W11: 11000 | Y11: =INT(VLOOKUP(U11, $AB$30:$AH$101, 7, FALSE)) -> 11000 | AB11: AI CCTV | AC11: 0 | AD11: 3000 | AE11: =INT($AE$3*AC11/$AC$3) -> 0 | AF11: 1 | AM11: Nautilus Log | AN11: 0 | AO11: 2000 | AP11: 0 | AQ11: 1
E12: MGPS | F12: No Need | H12: =IF(F12="Done", V12*VLOOKUP(E12, $AB$3:$AC$16, 2, FALSE), "") | I12: =IF(F12="Done", V12*VLOOKUP(E12, $AB$3:$AD$16, 3, FALSE), "") | J12: =IF(F12="Done", V12*VLOOKUP(E12, $AB$3:$AE$16, 4, FALSE), "") | U12: Britoil 21 | V12: =MIN(Y12/21388,1.3) -> 0.51430709 | W12: 11000 | Y12: =INT(VLOOKUP(U12, $AB$30:$AH$101, 7, FALSE)) -> 11000 | AB12: Nautilus Log | AC12: 0 | AD12: 1500 | AE12: =INT($AE$3*AC12/$AC$3) -> 0 | AF12: 1
E13: IWTM Filter | F13: In Process | H13: =IF(F13="Done", V13*VLOOKUP(E13, $AB$3:$AC$16, 2, FALSE), "") | I13: =IF(F13="Done", V13*VLOOKUP(E13, $AB$3:$AD$16, 3, FALSE), "") | J13: =IF(F13="Done", V13*VLOOKUP(E13, $AB$3:$AE$16, 4, FALSE), "") | U13: Britoil 21 | V13: =MIN(Y13/21388,1.3) -> 0.51430709 | W13: 11000 | Y13: =INT(VLOOKUP(U13, $AB$30:$AH$101, 7, FALSE)) -> 11000 | AB13: RE Conversion | AC13: 0 | AD13: 2000 | AE13: =INT($AE$3*AC13/$AC$3) -> 0 | AF13: 1
A14: a | B14: 2 | C14: Britoil 22 | D14: AHT E | E14: ↓ | H14: =IF(F14="Done", V14*VLOOKUP(E14, $AB$3:$AC$16, 2, FALSE), "") | I14: =IF(F14="Done", V14*VLOOKUP(E14, $AB$3:$AD$16, 3, FALSE), "") | J14: =IF(F14="Done", V14*VLOOKUP(E14, $AB$3:$AE$16, 4, FALSE), "") | K14: CE SARONHI BIN TOPIK | U14: =C14 -> Britoil 22 | V14: =MIN(Y14/21388,1.3) -> 0.51430709 | W14: 11000 | Y14: =INT(VLOOKUP(U14, $AB$30:$AH$101, 7, FALSE)) -> 11000 | AB14: Shore Generator | AC14: 10000 | AD14: 0 | AE14: =INT($AE$3*AC14/$AC$3) -> 58 | AF14: 1 | AI14: Devices (for 100tonnage) | AJ14: Scope 1 | AK14: Scope 3 | AL14: Co2 savings ton/year
E15: LED lights | F15: Not Installed | H15: =IF(F15="Done", V15*VLOOKUP(E15, $AB$3:$AC$16, 2, FALSE), "") | I15: =IF(F15="Done", V15*VLOOKUP(E15, $AB$3:$AD$16, 3, FALSE), "") | J15: =IF(F15="Done", V15*VLOOKUP(E15, $AB$3:$AE$16, 4, FALSE), "") | U15: Britoil 22 | V15: =MIN(Y15/21388,1.3) -> 0.51430709 | W15: 11000 | Y15: =INT(VLOOKUP(U15, $AB$30:$AH$101, 7, FALSE)) -> 11000 | AB15: Silicon Paint | AC15: 8000 | AD15: 5000 | AE15: =INT($AE$3*AC15/$AC$3) -> 46 | AF15: 1 | AI15: MGPS | AJ15: 11000 | AK15: 3200 | AL15: 64 | AM15: Bioguard / Discovery
E16: EFMS | F16: Not Installed | H16: =IF(F16="Done", V16*VLOOKUP(E16, $AB$3:$AC$16, 2, FALSE), "") | I16: =IF(F16="Done", V16*VLOOKUP(E16, $AB$3:$AD$16, 3, FALSE), "") | J16: =IF(F16="Done", V16*VLOOKUP(E16, $AB$3:$AE$16, 4, FALSE), "") | U16: Britoil 22 | V16: =MIN(Y16/21388,1.3) -> 0.51430709 | W16: 11000 | Y16: =INT(VLOOKUP(U16, $AB$30:$AH$101, 7, FALSE)) -> 11000 | AB16: IOW Separator | AC16: 0 | AD16: 3200 | AE16: =INT($AE$3*AC16/$AC$3) -> 0 | AF16: 1 | AI16: Chlorinator | AJ16: 0 | AK16: 3200 | AL16: 50 | AM16: good for CO2 / Discovery
E17: MGPS | F17: Done | G17: 1/12023 | H17: =IF(F17="Done", V17*VLOOKUP(E17, $AB$3:$AC$16, 2, FALSE), "") -> 5657.378 | I17: =IF(F17="Done", V17*VLOOKUP(E17, $AB$3:$AD$16, 3, FALSE), "") -> 1645.7827 | J17: =IF(F17="Done", V17*VLOOKUP(E17, $AB$3:$AE$16, 4, FALSE), "") -> 32.915654 | U17: Britoil 22 | V17: =MIN(Y17/21388,1.3) -> 0.51430709 | W17: 11000 | Y17: =INT(VLOOKUP(U17, $AB$30:$AH$101, 7, FALSE)) -> 11000 | AH17: CMCE LP | AI17: 0 | AJ17: 0 | AK17: 0 | AL17: all
E18: IWTM Filter | F18: In Process | H18: =IF(F18="Done", V18*VLOOKUP(E18, $AB$3:$AC$16, 2, FALSE), "") | I18: =IF(F18="Done", V18*VLOOKUP(E18, $AB$3:$AD$16, 3, FALSE), "") | J18: =IF(F18="Done", V18*VLOOKUP(E18, $AB$3:$AE$16, 4, FALSE), "") | U18: Britoil 22 | V18: =MIN(Y18/21388,1.3) -> 0.51430709 | W18: 11000 | Y18: =INT(VLOOKUP(U18, $AB$30:$AH$101, 7, FALSE)) -> 11000 | AH18: IWTM Filter | AI18: 2500 | AJ18: 3200 | AK18: 11 | AL18: Britoil 120
A19: a | B19: 3 | C19: Britoil 41 | D19: AHT E | E19: ↓ | H19: =IF(F19="Done", V19*VLOOKUP(E19, $AB$3:$AC$16, 2, FALSE), "") | I19: =IF(F19="Done", V19*VLOOKUP(E19, $AB$3:$AD$16, 3, FALSE), "") | J19: =IF(F19="Done", V19*VLOOKUP(E19, $AB$3:$AE$16, 4, FALSE), "") | U19: =C19 -> Britoil 41 | V19: =MIN(Y19/21388,1.3) -> 1.3 | W19: 42000 | X19: bride 1.3 | Y19: =INT(VLOOKUP(U19, $AB$30:$AH$101, 7, FALSE)) -> 33611 | AC19: TO | AD19: CHANGE / ADAPT | AE19: VERIFY | AH19: LED lights | AI19: 8300 | AJ19: 1000 | AK19: 45 | AL19: Discovery
E20: MGPS | F20: Done | H20: =IF(F20="Done", V20*VLOOKUP(E20, $AB$3:$AC$16, 2, FALSE), "") -> 14300 | I20: =IF(F20="Done", V20*VLOOKUP(E20, $AB$3:$AD$16, 3, FALSE), "") -> 4160 | J20: =IF(F20="Done", V20*VLOOKUP(E20, $AB$3:$AE$16, 4, FALSE), "") -> 83.2 | U20: Britoil 41 | V20: =MIN(Y20/21388,1.3) -> 1.3 | W20: 42000 | Y20: =INT(VLOOKUP(U20, $AB$30:$AH$101, 7, FALSE)) -> 33611 | AH20: EFMS | AI20: 16000 | AJ20: 100 | AK20: 85 | AL20: Defiance
E21: EFMS | F21: Not Installed | H21: =IF(F21="Done", V21*VLOOKUP(E21, $AB$3:$AC$16, 2, FALSE), "") | I21: =IF(F21="Done", V21*VLOOKUP(E21, $AB$3:$AD$16, 3, FALSE), "") | J21: =IF(F21="Done", V21*VLOOKUP(E21, $AB$3:$AE$16, 4, FALSE), "") | U21: Britoil 41 | V21: =MIN(Y21/21388,1.3) -> 1.3 | W21: 42000 | Y21: =INT(VLOOKUP(U21, $AB$30:$AH$101, 7, FALSE)) -> 33611 | AH21: EFMS not using Monitor | AI21: 8000 | AJ21: 100 | AK21: 40
E22: LED lights | F22: Done | H22: =IF(F22="Done", V22*VLOOKUP(E22, $AB$3:$AC$16, 2, FALSE), "") -> 10790 | I22: =IF(F22="Done", V22*VLOOKUP(E22, $AB$3:$AD$16, 3, FALSE), "") -> 5200 | J22: =IF(F22="Done", V22*VLOOKUP(E22, $AB$3:$AE$16, 4, FALSE), "") -> 110.5 | U22: Britoil 41 | V22: =MIN(Y22/21388,1.3) -> 1.3 | W22: 42000 | Y22: =INT(VLOOKUP(U22, $AB$30:$AH$101, 7, FALSE)) -> 33611 | AH22: AI CCTV | AI22: 0 | AJ22: 3000 | AK22: 0 | AL22: all
E23: IWTM Filter | F23: Done | H23: =IF(F23="Done", V23*VLOOKUP(E23, $AB$3:$AC$16, 2, FALSE), "") -> 1950 | I23: =IF(F23="Done", V23*VLOOKUP(E23, $AB$3:$AD$16, 3, FALSE), "") -> 8060 | J23: =IF(F23="Done", V23*VLOOKUP(E23, $AB$3:$AE$16, 4, FALSE), "") -> 10.4 | U23: Britoil 41 | V23: =MIN(Y23/21388,1.3) -> 1.3 | W23: 42000 | Y23: =INT(VLOOKUP(U23, $AB$30:$AH$101, 7, FALSE)) -> 33611 | AH23: Nautilus Log | AI23: 0 | AJ23: 2000 | AK23: 0 | AL23: all
A24: a | B24: 4 | C24: Britoil 60 | D24: AHT E | E24: ↓ | H24: =IF(F24="Done", V24*VLOOKUP(E24, $AB$3:$AC$16, 2, FALSE), "") | I24: =IF(F24="Done", V24*VLOOKUP(E24, $AB$3:$AD$16, 3, FALSE), "") | J24: =IF(F24="Done", V24*VLOOKUP(E24, $AB$3:$AE$16, 4, FALSE), "") | K24: ecr.britoil60@ship.britoil.com.sg | U24: =C24 -> Britoil 60 | V24: =MIN(Y24/21388,1.3) -> 1.3 | W24: 32000 | X24: bride 1.3 | Y24: =INT(VLOOKUP(U24, $AB$30:$AH$101, 7, FALSE)) -> 32083
E25: MGPS | F25: Done | H25: =IF(F25="Done", V25*VLOOKUP(E25, $AB$3:$AC$16, 2, FALSE), "") -> 14300 | I25: =IF(F25="Done", V25*VLOOKUP(E25, $AB$3:$AD$16, 3, FALSE), "") -> 4160 | J25: =IF(F25="Done", V25*VLOOKUP(E25, $AB$3:$AE$16, 4, FALSE), "") -> 83.2 | U25: Britoil 60 | V25: =MIN(Y25/21388,1.3) -> 1.3 | W25: 32000 | Y25: =INT(VLOOKUP(U25, $AB$30:$AH$101, 7, FALSE)) -> 32083 | AJ25: TO CHANGE
E26: EFMS | F26: Not Installed | H26: =IF(F26="Done", V26*VLOOKUP(E26, $AB$3:$AC$16, 2, FALSE), "") | I26: =IF(F26="Done", V26*VLOOKUP(E26, $AB$3:$AD$16, 3, FALSE), "") | J26: =IF(F26="Done", V26*VLOOKUP(E26, $AB$3:$AE$16, 4, FALSE), "") | U26: Britoil 60 | V26: =MIN(Y26/21388,1.3) -> 1.3 | W26: 32000 | Y26: =INT(VLOOKUP(U26, $AB$30:$AH$101, 7, FALSE)) -> 32083
E27: LED lights | F27: Not Installed | H27: =IF(F27="Done", V27*VLOOKUP(E27, $AB$3:$AC$16, 2, FALSE), "") | I27: =IF(F27="Done", V27*VLOOKUP(E27, $AB$3:$AD$16, 3, FALSE), "") | J27: =IF(F27="Done", V27*VLOOKUP(E27, $AB$3:$AE$16, 4, FALSE), "") | U27: Britoil 60 | V27: =MIN(Y27/21388,1.3) -> 1.3 | W27: 32000 | Y27: =INT(VLOOKUP(U27, $AB$30:$AH$101, 7, FALSE)) -> 32083
E28: IWTM Filter | F28: Done | G28: 45397 | H28: =IF(F28="Done", V28*VLOOKUP(E28, $AB$3:$AC$16, 2, FALSE), "") -> 1950 | I28: =IF(F28="Done", V28*VLOOKUP(E28, $AB$3:$AD$16, 3, FALSE), "") -> 8060 | J28: =IF(F28="Done", V28*VLOOKUP(E28, $AB$3:$AE$16, 4, FALSE), "") -> 10.4 | U28: Britoil 60 | V28: =MIN(Y28/21388,1.3) -> 1.3 | W28: 32000 | Y28: =INT(VLOOKUP(U28, $AB$30:$AH$101, 7, FALSE)) -> 32083
A29: a | B29: 5 | C29: Britoil 61 | D29: AHT E | E29: ↓ | H29: =IF(F29="Done", V29*VLOOKUP(E29, $AB$3:$AC$16, 2, FALSE), "") | I29: =IF(F29="Done", V29*VLOOKUP(E29, $AB$3:$AD$16, 3, FALSE), "") | J29: =IF(F29="Done", V29*VLOOKUP(E29, $AB$3:$AE$16, 4, FALSE), "") | U29: =C29 -> Britoil 61 | V29: =MIN(Y29/21388,1.3) -> 1.3 | W29: 32000 | X29: bride 1.3 | Y29: =INT(VLOOKUP(U29, $AB$30:$AH$101, 7, FALSE)) -> 32083 | AB29: Brake Horsepower | AC29: Bollard Pull | AD29: Dimensions | AE29: Specifications
E30: MGPS | F30: Done | H30: =IF(F30="Done", V30*VLOOKUP(E30, $AB$3:$AC$16, 2, FALSE), "") -> 14300 | I30: =IF(F30="Done", V30*VLOOKUP(E30, $AB$3:$AD$16, 3, FALSE), "") -> 4160 | J30: =IF(F30="Done", V30*VLOOKUP(E30, $AB$3:$AE$16, 4, FALSE), "") -> 83.2 | U30: {=IF(C30="",INDEX(C27:C30,MATCH(TRUE,INDEX((C27:C30<>""),0),0)),C30)} -> Britoil 61 | V30: =MIN(Y30/21388,1.3) -> 1.3 | W30: 32000 | Y30: =INT(VLOOKUP(U30, $AB$30:$AH$101, 7, FALSE)) -> 32083 | AB30: Britoil 21 | AC30: 3600 | AD30: 52 | AE30: 43.00m x 12.60m | AF30: 14.4 | AG30: 1 | AH30: 11000
E31: EFMS | F31: Not Installed | H31: =IF(F31="Done", V31*VLOOKUP(E31, $AB$3:$AC$16, 2, FALSE), "") | I31: =IF(F31="Done", V31*VLOOKUP(E31, $AB$3:$AD$16, 3, FALSE), "") | J31: =IF(F31="Done", V31*VLOOKUP(E31, $AB$3:$AE$16, 4, FALSE), "") | U31: {=IF(C31="",INDEX(C28:C31,MATCH(TRUE,INDEX((C28:C31<>""),0),0)),C31)} -> Britoil 61 | V31: =MIN(Y31/21388,1.3) -> 1.3 | W31: 32000 | Y31: =INT(VLOOKUP(U31, $AB$30:$AH$101, 7, FALSE)) -> 32083 | AB31: Britoil 22 | AC31: 3600 | AD31: 52 | AE31: 43.00m x 12.60m | AF31: 14.4 | AG31: 1 | AH31: =$AH$30 *AC31/ $AC$30 -> 11000
E32: LED lights | F32: Not Installed | H32: =IF(F32="Done", V32*VLOOKUP(E32, $AB$3:$AC$16, 2, FALSE), "") | I32: =IF(F32="Done", V32*VLOOKUP(E32, $AB$3:$AD$16, 3, FALSE), "") | J32: =IF(F32="Done", V32*VLOOKUP(E32, $AB$3:$AE$16, 4, FALSE), "") | U32: {=IF(C32="",INDEX(C28:C32,MATCH(TRUE,INDEX((C28:C32<>""),0),0)),C32)} -> Britoil 61 | V32: =MIN(Y32/21388,1.3) -> 1.3 | W32: 32000 | Y32: =INT(VLOOKUP(U32, $AB$30:$AH$101, 7, FALSE)) -> 32083 | AB32: Britoil 41 | AC32: 11000 | AD32: 150 | AE32: 60.00m x 17.80m | AF32: 13.6 | AG32: 0.94405594 | AH32: =$AH$30 *AC32/ $AC$30 -> 33611.111
E33: IWTM Filter | F33: Done | H33: =IF(F33="Done", V33*VLOOKUP(E33, $AB$3:$AC$16, 2, FALSE), "") -> 1950 | I33: =IF(F33="Done", V33*VLOOKUP(E33, $AB$3:$AD$16, 3, FALSE), "") -> 8060 | J33: =IF(F33="Done", V33*VLOOKUP(E33, $AB$3:$AE$16, 4, FALSE), "") -> 10.4 | U33: {=IF(C33="",INDEX(C29:C33,MATCH(TRUE,INDEX((C29:C33<>""),0),0)),C33)} -> Britoil 61 | V33: =MIN(Y33/21388,1.3) -> 1.3 | W33: 32000 | Y33: =INT(VLOOKUP(U33, $AB$30:$AH$101, 7, FALSE)) -> 32083 | AB33: Britoil 60 | AC33: 10500 | AD33: 130 | AE33: 51.00m x 13.00m | AF33: 12.4 | AG33: 0.85714286 | AH33: =$AH$30 *AC33/ $AC$30 -> 32083.333
A34: a | B34: 6 | C34: Britoil 62 | D34: AHT E | E34: ↓ | H34: =IF(F34="Done", V34*VLOOKUP(E34, $AB$3:$AC$16, 2, FALSE), "") | I34: =IF(F34="Done", V34*VLOOKUP(E34, $AB$3:$AD$16, 3, FALSE), "") | J34: =IF(F34="Done", V34*VLOOKUP(E34, $AB$3:$AE$16, 4, FALSE), "") | U34: {=IF(C34="",INDEX(C30:C34,MATCH(TRUE,INDEX((C30:C34<>""),0),0)),C34)} -> Britoil 62 | V34: =MIN(Y34/21388,1.3) -> 0.77146063 | W34: 16000 | Y34: =INT(VLOOKUP(U34, $AB$30:$AH$101, 7, FALSE)) -> 16500 | AB34: Britoil 61 | AC34: 10500 | AD34: 130 | AE34: 51.00m x 13.00m | AF34: 12.4 | AG34: 0.85714286 | AH34: =$AH$30 *AC34/ $AC$30 -> 32083.333
E35: MGPS | F35: Done | H35: =IF(F35="Done", V35*VLOOKUP(E35, $AB$3:$AC$16, 2, FALSE), "") -> 8486.067 | I35: =IF(F35="Done", V35*VLOOKUP(E35, $AB$3:$AD$16, 3, FALSE), "") -> 2468.674 | J35: =IF(F35="Done", V35*VLOOKUP(E35, $AB$3:$AE$16, 4, FALSE), "") -> 49.37348 | U35: {=IF(C35="",INDEX(C32:C35,MATCH(TRUE,INDEX((C32:C35<>""),0),0)),C35)} -> Britoil 62 | V35: =MIN(Y35/21388,1.3) -> 0.77146063 | W35: 16000 | Y35: =INT(VLOOKUP(U35, $AB$30:$AH$101, 7, FALSE)) -> 16500 | AB35: Britoil 62 | AC35: 5400 | AD35: 70 | AE35: 40.00m x 11.40m | AF35: 13 | AG35: 0.8974359 | AH35: =$AH$30 *AC35/ $AC$30 -> 16500
E36: EFMS | F36: Not Installed | H36: =IF(F36="Done", V36*VLOOKUP(E36, $AB$3:$AC$16, 2, FALSE), "") | I36: =IF(F36="Done", V36*VLOOKUP(E36, $AB$3:$AD$16, 3, FALSE), "") | J36: =IF(F36="Done", V36*VLOOKUP(E36, $AB$3:$AE$16, 4, FALSE), "") | U36: {=IF(C36="",INDEX(C33:C36,MATCH(TRUE,INDEX((C33:C36<>""),0),0)),C36)} -> Britoil 62 | V36: =MIN(Y36/21388,1.3) -> 0.77146063 | W36: 16000 | Y36: =INT(VLOOKUP(U36, $AB$30:$AH$101, 7, FALSE)) -> 16500 | AB36: Britoil 63 | AC36: 5400 | AD36: 70 | AE36: 40.00m x 11.40m | AF36: 13 | AG36: 0.8974359 | AH36: =$AH$30 *AC36/ $AC$30 -> 16500
E37: LED lights | F37: Not Installed | H37: =IF(F37="Done", V37*VLOOKUP(E37, $AB$3:$AC$16, 2, FALSE), "") | I37: =IF(F37="Done", V37*VLOOKUP(E37, $AB$3:$AD$16, 3, FALSE), "") | J37: =IF(F37="Done", V37*VLOOKUP(E37, $AB$3:$AE$16, 4, FALSE), "") | U37: {=IF(C37="",INDEX(C33:C37,MATCH(TRUE,INDEX((C33:C37<>""),0),0)),C37)} -> Britoil 62 | V37: =MIN(Y37/21388,1.3) -> 0.77146063 | W37: 16000 | Y37: =INT(VLOOKUP(U37, $AB$30:$AH$101, 7, FALSE)) -> 16500 | AB37: Britoil 64 | AC37: 5400 | AD37: 70 | AE37: 40.00m x 11.40m | AF37: 13 | AG37: 0.8974359 | AH37: =$AH$30 *AC37/ $AC$30 -> 16500
E38: IWTM Filter | F38: Done | H38: =IF(F38="Done", V38*VLOOKUP(E38, $AB$3:$AC$16, 2, FALSE), "") -> 1157.1909 | I38: =IF(F38="Done", V38*VLOOKUP(E38, $AB$3:$AD$16, 3, FALSE), "") -> 4783.0559 | J38: =IF(F38="Done", V38*VLOOKUP(E38, $AB$3:$AE$16, 4, FALSE), "") -> 6.1716851 | U38: {=IF(C38="",INDEX(C34:C38,MATCH(TRUE,INDEX((C34:C38<>""),0),0)),C38)} -> Britoil 62 | V38: =MIN(Y38/21388,1.3) -> 0.77146063 | W38: 16000 | Y38: =INT(VLOOKUP(U38, $AB$30:$AH$101, 7, FALSE)) -> 16500 | AB38: Britoil 65 | AC38: 5400 | AD38: 70 | AE38: 40.00m x 11.40m | AF38: 13 | AG38: 0.8974359 | AH38: =$AH$30 *AC38/ $AC$30 -> 16500
A39: a | B39: 7 | C39: Britoil 63 | D39: AHT E | E39: ↓ | H39: =IF(F39="Done", V39*VLOOKUP(E39, $AB$3:$AC$16, 2, FALSE), "") | I39: =IF(F39="Done", V39*VLOOKUP(E39, $AB$3:$AD$16, 3, FALSE), "") | J39: =IF(F39="Done", V39*VLOOKUP(E39, $AB$3:$AE$16, 4, FALSE), "") | U39: {=IF(C39="",INDEX(C35:C39,MATCH(TRUE,INDEX((C35:C39<>""),0),0)),C39)} -> Britoil 63 | V39: =MIN(Y39/21388,1.3) -> 0.77146063 | W39: 16000 | Y39: =INT(VLOOKUP(U39, $AB$30:$AH$101, 7, FALSE)) -> 16500 | AB39: Britoil 66 | AC39: 5400 | AD39: 70 | AE39: 40.00m x 11.40m | AF39: 13 | AG39: 0.8974359 | AH39: =$AH$30 *AC39/ $AC$30 -> 16500
E40: MGPS | F40: Done | H40: =IF(F40="Done", V40*VLOOKUP(E40, $AB$3:$AC$16, 2, FALSE), "") -> 8486.067 | I40: =IF(F40="Done", V40*VLOOKUP(E40, $AB$3:$AD$16, 3, FALSE), "") -> 2468.674 | J40: =IF(F40="Done", V40*VLOOKUP(E40, $AB$3:$AE$16, 4, FALSE), "") -> 49.37348 | U40: {=IF(C40="",INDEX(C37:C40,MATCH(TRUE,INDEX((C37:C40<>""),0),0)),C40)} -> Britoil 63 | V40: =MIN(Y40/21388,1.3) -> 0.77146063 | W40: 16000 | Y40: =INT(VLOOKUP(U40, $AB$30:$AH$101, 7, FALSE)) -> 16500 | AB40: Britoil 67 | AC40: 5400 | AD40: 70 | AE40: 40.00m x 11.40m | AF40: 13 | AG40: 0.8974359 | AH40: =$AH$30 *AC40/ $AC$30 -> 16500
...

Sheet Summary
A2: Device | B2: Scopes | C2: Total Installed | D2: In process | E2: Needed | F2: Percentage in move | G2: POC OK? | I2: ↓ | J2: Last 12 months | K2: Goal next 12 months | N2: Savings by each | O2: Co2 | R2: instal progr | T2: Installed | U2: In Progress | V2: Missing | W2: Needed
A3: MGPS | B3: 1, 3 | C3: =COUNTIFS(Tracker!E:E,A3,Tracker!F:F,"Done") -> 48 | D3: =COUNTIFS(Tracker!E:E,A3,Tracker!F:F,"In Process") -> 1 | E3: =COUNTIF(Tracker!E:E,A3)-COUNTIFS(Tracker!E:E,A3,Tracker!F:F,"No need") -> 67 | F3: =(C3+D3)/E3 -> 0.73134328 | G3: TRUE | I3: Installation Progress | J3: =R18 -> 0.64709378 | K3: 0.8 | N3: =C3*(Tracker!AC3+Tracker!AD3) -> 681600 | O3: =C3*(Tracker!AE3) -> 3072 | Q3: =A3 -> MGPS | R3: =F3 -> 0.73134328 | S3: Current 2025 | T3: =SUM(C3:C17) -> 218 | U3: =SUM(D3:D17) -> 26 | V3: =W4-T3-U3 -> 306 | W3: 0
A4: EFMS | B4: 1, 3 | C4: =COUNTIFS(Tracker!E:E,A4,Tracker!F:F,"Done") -> 17 | D4: =COUNTIFS(Tracker!E:E,A4,Tracker!F:F,"In Process") -> 1 | E4: =COUNTIF(Tracker!E:E,A4)-COUNTIFS(Tracker!E:E,A4,Tracker!F:F,"No need") -> 70 | F4: =(C4+D4)/E4 -> 0.25714286 | G4: TRUE | I4: Vessel Updated Info | J4: =Tracker!A474 -> 0.93055556 | K4: 1 | N4: =C4*(Tracker!AC9+Tracker!AD9) -> 289000 | O4: =C4*(Tracker!AE4) -> 1479 | Q4: =A4 -> EFMS | R4: =F4 -> 0.25714286 | S4: Needed | T4: 0 | U4: 0 | V4: 0 | W4: =SUM(E3:E17) -> 550
A5: IWTM Filter | B5: 3 | C5: =COUNTIFS(Tracker!E:E,A5,Tracker!F:F,"Done") -> 29 | D5: =COUNTIFS(Tracker!E:E,A5,Tracker!F:F,"In Process") -> 13 | E5: =COUNTIF(Tracker!E:E,A5)-COUNTIFS(Tracker!E:E,A5,Tracker!F:F,"No need") -> 44 | F5: =(C5+D5)/E5 -> 0.95454545 | G5: TRUE | I5: Fleet estimated Savings | J5: =Tracker!AD123 -> 0.073772554 | K5: 0.2 | N5: =C5*(Tracker!AC7+Tracker!AD7) -> 223300 | O5: =C5*(Tracker!AE5) -> 0 | Q5: =A5 -> IWTM Filter | R5: =F5 -> 0.95454545 | S5: Goal 2026 | T5: 250 | U5: 75 | V5: 50 | W5: 0
A6: CJC Filter | B6: 3 | C6: =COUNTIFS(Tracker!E:E,A6,Tracker!F:F,"Done") -> 5 | D6: =COUNTIFS(Tracker!E:E,A6,Tracker!F:F,"In Process") -> 3 | E6: =COUNTIF(Tracker!E:E,A6)-COUNTIFS(Tracker!E:E,A6,Tracker!F:F,"No need") -> 8 | F6: =(C6+D6)/E6 -> 1 | G6: TRUE
A7: CMCE LP | B7: 3 | C7: =COUNTIFS(Tracker!E:E,A7,Tracker!F:F,"Done") -> 12 | D7: =COUNTIFS(Tracker!E:E,A7,Tracker!F:F,"In Process") -> 1 | E7: =COUNTIF(Tracker!E:E,A7)-COUNTIFS(Tracker!E:E,A7,Tracker!F:F,"No need") -> 45 | F7: =(C7+D7)/E7 -> 0.28888889 | G7: TRUE | J7: =Tracker!AD121 -> 22926 | N7: =C7*(Tracker!AC6+Tracker!AD6) -> 90000 | O7: =C7*(Tracker!AE6) -> 168 | Q7: =A7 -> CMCE LP | R7: =F7 -> 0.28888889
A8: LED lights | B8: 1, 3 | C8: =COUNTIFS(Tracker!E:E,A8,Tracker!F:F,"Done") -> 26 | D8: =COUNTIFS(Tracker!E:E,A8,Tracker!F:F,"In Process") -> 2 | E8: =COUNTIF(Tracker!E:E,A8)-COUNTIFS(Tracker!E:E,A8,Tracker!F:F,"No need") -> 70 | F8: =(C8+D8)/E8 -> 0.4 | G8: TRUE | J8: 72 | N8: =C8*(Tracker!AC8+Tracker!AD8) -> 319800 | O8: =C8*(Tracker!AE7) -> 208 | Q8: =A8 -> LED lights | R8: =F8 -> 0.4
A9: Chlorinator | B9: 3 | C9: =COUNTIFS(Tracker!E:E,A9,Tracker!F:F,"Done") -> 1 | D9: =COUNTIFS(Tracker!E:E,A9,Tracker!F:F,"In Process") -> 1 | E9: =COUNTIF(Tracker!E:E,A9)-COUNTIFS(Tracker!E:E,A9,Tracker!F:F,"No need") -> 2 | F9: =(C9+D9)/E9 -> 1 | G9: TRUE | N9: =C9*(Tracker!AC8+Tracker!AD8) -> 12300 | O9: =C9*(Tracker!AE8) -> 85 | Q9: =A9 -> Chlorinator | R9: =F9 -> 1
A10: Deva Paint | B10: 3 | C10: =COUNTIFS(Tracker!E:E,A10,Tracker!F:F,"Done") -> 1 | D10: =COUNTIFS(Tracker!E:E,A10,Tracker!F:F,"In Process") -> 0 | E10: 72 | F10: =(C10+D10)/E10 -> 0.013888889 | G10: FALSE | N10: 0 | O10: 0 | Q10: =A10 -> Deva Paint | R10: =F10 -> 0.013888889
A11: AI CCTV | B11: 3 | C11: =COUNTIFS(Tracker!E:E,A11,Tracker!F:F,"Done") -> 5 | D11: =COUNTIFS(Tracker!E:E,A11,Tracker!F:F,"In Process") -> 0 | E11: =COUNTIF(Tracker!E:E,A11)-COUNTIFS(Tracker!E:E,A11,Tracker!F:F,"No need") -> 10 | F11: =(C11+D11)/E11 -> 0.5 | G11: FALSE | N11: =C11*(Tracker!AC10+Tracker!AD10) -> 20000 | O11: =C11*(Tracker!AE10) -> 150 | Q11: =A11 -> AI CCTV | R11: =F11 -> 0.5
A12: Spinergie Fleet | B12: 1,3 | C12: =COUNTIFS(Tracker!E:E,A12,Tracker!F:F,"Done") -> 0 | D12: =COUNTIFS(Tracker!E:E,A12,Tracker!F:F,"In Process") -> 2 | E12: 72 | F12: =(C12+D12)/E12 -> 0.027777778 | G12: FALSE | Q12: =A12 -> Spinergie Fleet
A13: Nautilus Log | B13: 3 | C13: 70 | D13: =COUNTIFS(Tracker!E:E,A13,Tracker!F:F,"In Process") -> 0 | E13: 72 | F13: =(C13+D13)/E13 -> 0.97222222 | G13: TRUE | N13: =C13*(Tracker!AC11+Tracker!AD11) -> 210000 | O13: =C13*(Tracker!AE11) -> 0 | Q13: =A13 -> Nautilus Log | R13: =F13 -> 0.97222222
A14: RE Conversion | B14: 2 | C14: =COUNTIFS(Tracker!E:E,A14,Tracker!F:F,"Done") -> 1 | D14: =COUNTIFS(Tracker!E:E,A14,Tracker!F:F,"In Process") -> 0 | E14: =COUNTIF(Tracker!E:E,A14)-COUNTIFS(Tracker!E:E,A14,Tracker!F:F,"No need") -> 1 | F14: =(C14+D14)/E14 -> 1 | G14: TRUE | N14: =C14*(Tracker!AC12+Tracker!AD12) -> 1500 | O14: =C14*(Tracker!AE12) -> 0 | Q14: =A14 -> RE Conversion | R14: =F14 -> 1
A15: Silicon Paint | B15: 1,3 | C15: =COUNTIFS(Tracker!E:E,A15,Tracker!F:F,"Done") -> 1 | D15: =COUNTIFS(Tracker!E:E,A15,Tracker!F:F,"In Process") -> 1 | E15: =COUNTIF(Tracker!E:E,A15)-COUNTIFS(Tracker!E:E,A15,Tracker!F:F,"No need") -> 8 | F15: =(C15+D15)/E15 -> 0.25 | G15: FALSE | Q15: =A15 -> Silicon Paint
A16: Shore Generator | B16: 2 | C16: =COUNTIFS(Tracker!E:E,A16,Tracker!F:F,"Done") -> 2 | D16: =COUNTIFS(Tracker!E:E,A16,Tracker!F:F,"In Process") -> 0 | E16: =COUNTIF(Tracker!E:E,A16)-COUNTIFS(Tracker!E:E,A16,Tracker!F:F,"No need") -> 8 | F16: =(C16+D16)/E16 -> 0.25 | G16: FALSE | N16: =C16*(Tracker!#REF!+Tracker!#REF!) -> #REF! | O16: =C16*(Tracker!#REF!) -> #REF! | Q16: =A16 -> Shore Generator
A17: IOW Separator | B17: 3 | C17: =COUNTIFS(Tracker!E:E,A17,Tracker!F:F,"Done") -> 0 | D17: =COUNTIFS(Tracker!E:E,A17,Tracker!F:F,"In Process") -> 1 | E17: =COUNTIF(Tracker!E:E,A17)-COUNTIFS(Tracker!E:E,A17,Tracker!F:F,"No need") -> 1 | F17: =(C17+D17)/E17 -> 1 | G17: FALSE | N17: =C17*(Tracker!AC12+Tracker!AD12) -> 0 | O17: =C17*(Tracker!AE12) -> 0 | Q17: =A17 -> IOW Separator | R17: =F17 -> 1
Q18: Average | R18: =AVERAGE(R3:R17) -> 0.64709378
B20: #VALUE! | D20: Best Savings → | E20: =INDEX(A26:A94, MATCH(G21, B26:B94, 0)) -> Britoil Defiance
B21: Total Savings | C21: =SUM(Tracker!H9:H491)+SUM(Tracker!I9:I491)+C13*Tracker!AD12 -> 1670508.1 | G21: =MAX(B26:B92) -> 79887.582
B22: CO2eq (tons) | C22: =SUM(Tracker!J9:J491) -> 7055.9398 | D22: Best Vessel → | E22: BOS Princess
B23: New Initiatives | C23: 15
A25: BOS DUBAI | B25: =SUM(B26:B53) -> 694442.62 | C25: BOS SG | D25: =SUM(D26:D53) -> 393234.93 | E25: BOS ITALY | F25: =SUM(F26:F53) -> 477830.55
A26: Britoil 21 | B26: =SUMIF(Tracker!$U$9:$U$491, A26, Tracker!$H$9:$H$491)+SUMIF(Tracker!$U$9:$U$491, A26, Tracker!$I$9:$I$491) -> 0 | C26: Britoil Diligance | D26: =SUMIF(Tracker!$U$9:$U$491, C26, Tracker!$H$9:$H$491)+SUMIF(Tracker!$U$9:$U$491, C26, Tracker!$I$9:$I$491) -> 14057.471 | E26: Britoil Guardian | F26: =SUMIF(Tracker!$U$9:$U$491, E26, Tracker!$H$9:$H$491)+SUMIF(Tracker!$U$9:$U$491, E26, Tracker!$I$9:$I$491) -> 0
A27: Britoil 22 | B27: =SUMIF(Tracker!$U$9:$U$491, A27, Tracker!$H$9:$H$491)+SUMIF(Tracker!$U$9:$U$491, A27, Tracker!$I$9:$I$491) -> 7303.1607 | C27: Britoil Discovery | D27: =SUMIF(Tracker!$U$9:$U$491, C27, Tracker!$H$9:$H$491)+SUMIF(Tracker!$U$9:$U$491, C27, Tracker!$I$9:$I$491) -> 34700 | E27: BOS Apollo | F27: =SUMIF(Tracker!$U$9:$U$491, E27, Tracker!$H$9:$H$491)+SUMIF(Tracker!$U$9:$U$491, E27, Tracker!$I$9:$I$491) -> 19497.101 | Q27: Vessels | R27: total | S27: Average/vessel
A28: Britoil 41 | B28: =SUMIF(Tracker!$U$9:$U$491, A28, Tracker!$H$9:$H$491)+SUMIF(Tracker!$U$9:$U$491, A28, Tracker!$I$9:$I$491) -> 44460 | C28: Britoil Dragon | D28: =SUMIF(Tracker!$U$9:$U$491, C28, Tracker!$H$9:$H$491)+SUMIF(Tracker!$U$9:$U$491, C28, Tracker!$I$9:$I$491) -> 19323.279 | E28: BOS Aphrodite | F28: =SUMIF(Tracker!$U$9:$U$491, E28, Tracker!$H$9:$H$491)+SUMIF(Tracker!$U$9:$U$491, E28, Tracker!$I$9:$I$491) -> 10447.503 | Q28: BOS ITALY | R28: =F25 -> 477830.55 | S28: =R28/23 -> 20775.241
A29: Britoil 60 | B29: =SUMIF(Tracker!$U$9:$U$491, A29, Tracker!$H$9:$H$491)+SUMIF(Tracker!$U$9:$U$491, A29, Tracker!$I$9:$I$491) -> 28470 | C29: Britoil Defiance | D29: =SUMIF(Tracker!$U$9:$U$491, C29, Tracker!$H$9:$H$491)+SUMIF(Tracker!$U$9:$U$491, C29, Tracker!$I$9:$I$491) -> 79887.582 | E29: BOS Chablis | F29: =SUMIF(Tracker!$U$9:$U$491, E29, Tracker!$H$9:$H$491)+SUMIF(Tracker!$U$9:$U$491, E29, Tracker!$I$9:$I$491) -> 20336.446 | Q29: BOS SG | R29: =D25 -> 393234.93 | S29: =R29/16 -> 24577.183
A30: Britoil 61 | B30: =SUMIF(Tracker!$U$9:$U$491, A30, Tracker!$H$9:$H$491)+SUMIF(Tracker!$U$9:$U$491, A30, Tracker!$I$9:$I$491) -> 28470 | C30: Britoil Defender | D30: =SUMIF(Tracker!$U$9:$U$491, C30, Tracker!$H$9:$H$491)+SUMIF(Tracker!$U$9:$U$491, C30, Tracker!$I$9:$I$491) -> 10286.142 | E30: BOS Champagne | F30: =SUMIF(Tracker!$U$9:$U$491, E30, Tracker!$H$9:$H$491)+SUMIF(Tracker!$U$9:$U$491, E30, Tracker!$I$9:$I$491) -> 20336.446 | Q30: BOS DUBAI | R30: =B25 -> 694442.62 | S30: =R30/28 -> 24801.522
A31: Britoil 62 | B31: =SUMIF(Tracker!$U$9:$U$491, A31, Tracker!$H$9:$H$491)+SUMIF(Tracker!$U$9:$U$491, A31, Tracker!$I$9:$I$491) -> 16894.988 | C31: ENA Habitat | D31: =SUMIF(Tracker!$U$9:$U$491, C31, Tracker!$H$9:$H$491)+SUMIF(Tracker!$U$9:$U$491, C31, Tracker!$I$9:$I$491) -> 10543.104 | E31: BOS Tethys | F31: =SUMIF(Tracker!$U$9:$U$491, E31, Tracker!$H$9:$H$491)+SUMIF(Tracker!$U$9:$U$491, E31, Tracker!$I$9:$I$491) -> 19497.101
A32: Britoil 63 | B32: =SUMIF(Tracker!$U$9:$U$491, A32, Tracker!$H$9:$H$491)+SUMIF(Tracker!$U$9:$U$491, A32, Tracker!$I$9:$I$491) -> 26923.976 | C32: Nautical Anisha | D32: =SUMIF(Tracker!$U$9:$U$491, C32, Tracker!$H$9:$H$491)+SUMIF(Tracker!$U$9:$U$491, C32, Tracker!$I$9:$I$491) -> 12171.713 | E32: BOS Theia | F32: =SUMIF(Tracker!$U$9:$U$491, E32, Tracker!$H$9:$H$491)+SUMIF(Tracker!$U$9:$U$491, E32, Tracker!$I$9:$I$491) -> 0
A33: Britoil 64 | B33: =SUMIF(Tracker!$U$9:$U$491, A33, Tracker!$H$9:$H$491)+SUMIF(Tracker!$U$9:$U$491, A33, Tracker!$I$9:$I$491) -> 10954.741 | C33: Nautical Aisia | D33: =SUMIF(Tracker!$U$9:$U$491, C33, Tracker!$H$9:$H$491)+SUMIF(Tracker!$U$9:$U$491, C33, Tracker!$I$9:$I$491) -> 12171.713 | E33: BOS Triton | F33: =SUMIF(Tracker!$U$9:$U$491, E33, Tracker!$H$9:$H$491)+SUMIF(Tracker!$U$9:$U$491, E33, Tracker!$I$9:$I$491) -> 0
A34: Britoil 65 | B34: =SUMIF(Tracker!$U$9:$U$491, A34, Tracker!$H$9:$H$491)+SUMIF(Tracker!$U$9:$U$491, A34, Tracker!$I$9:$I$491) -> 10954.741 | C34: BOS Ares | D34: =SUMIF(Tracker!$U$9:$U$491, C34, Tracker!$H$9:$H$491)+SUMIF(Tracker!$U$9:$U$491, C34, Tracker!$I$9:$I$491) -> 32004.676 | E34: BOS Pride | F34: =SUMIF(Tracker!$U$9:$U$491, E34, Tracker!$H$9:$H$491)+SUMIF(Tracker!$U$9:$U$491, E34, Tracker!$I$9:$I$491) -> 48229.699
A35: Britoil 66 | B35: =SUMIF(Tracker!$U$9:$U$491, A35, Tracker!$H$9:$H$491)+SUMIF(Tracker!$U$9:$U$491, A35, Tracker!$I$9:$I$491) -> 16894.988 | C35: BOS Athena | D35: =SUMIF(Tracker!$U$9:$U$491, C35, Tracker!$H$9:$H$491)+SUMIF(Tracker!$U$9:$U$491, C35, Tracker!$I$9:$I$491) -> 21557.172 | E35: BOS Princess | F35: =SUMIF(Tracker!$U$9:$U$491, E35, Tracker!$H$9:$H$491)+SUMIF(Tracker!$U$9:$U$491, E35, Tracker!$I$9:$I$491) -> 23900
A36: Britoil 67 | B36: =SUMIF(Tracker!$U$9:$U$491, A36, Tracker!$H$9:$H$491)+SUMIF(Tracker!$U$9:$U$491, A36, Tracker!$I$9:$I$491) -> 16894.988 | C36: BOS Atlanta | D36: =SUMIF(Tracker!$U$9:$U$491, C36, Tracker!$H$9:$H$491)+SUMIF(Tracker!$U$9:$U$491, C36, Tracker!$I$9:$I$491) -> 21557.172 | E36: BOS Pool | F36: =SUMIF(Tracker!$U$9:$U$491, E36, Tracker!$H$9:$H$491)+SUMIF(Tracker!$U$9:$U$491, E36, Tracker!$I$9:$I$491) -> 0
A37: Britoil 70 | B37: =SUMIF(Tracker!$U$9:$U$491, A37, Tracker!$H$9:$H$491)+SUMIF(Tracker!$U$9:$U$491, A37, Tracker!$I$9:$I$491) -> 27317.748 | C37: BOS Atlas | D37: =SUMIF(Tracker!$U$9:$U$491, C37, Tracker!$H$9:$H$491)+SUMIF(Tracker!$U$9:$U$491, C37, Tracker!$I$9:$I$491) -> 21557.172 | E37: BOS Base | F37: =SUMIF(Tracker!$U$9:$U$491, E37, Tracker!$H$9:$H$491)+SUMIF(Tracker!$U$9:$U$491, E37, Tracker!$I$9:$I$491) -> 12171.713
A38: Britoil 71 | B38: =SUMIF(Tracker!$U$9:$U$491, A38, Tracker!$H$9:$H$491)+SUMIF(Tracker!$U$9:$U$491, A38, Tracker!$I$9:$I$491) -> 17730.765 | C38: BOS Challenge | D38: =SUMIF(Tracker!$U$9:$U$491, C38, Tracker!$H$9:$H$491)+SUMIF(Tracker!$U$9:$U$491, C38, Tracker!$I$9:$I$491) -> 34358.379 | E38: BOS Patience | F38: =SUMIF(Tracker!$U$9:$U$491, E38, Tracker!$H$9:$H$491)+SUMIF(Tracker!$U$9:$U$491, E38, Tracker!$I$9:$I$491) -> 31043.459
A39: Britoil 72 | B39: =SUMIF(Tracker!$U$9:$U$491, A39, Tracker!$H$9:$H$491)+SUMIF(Tracker!$U$9:$U$491, A39, Tracker!$I$9:$I$491) -> 44842.341 | C39: BOS Champion | D39: =SUMIF(Tracker!$U$9:$U$491, C39, Tracker!$H$9:$H$491)+SUMIF(Tracker!$U$9:$U$491, C39, Tracker!$I$9:$I$491) -> 47544.567 | E39: BOS Patriot | F39: =SUMIF(Tracker!$U$9:$U$491, E39, Tracker!$H$9:$H$491)+SUMIF(Tracker!$U$9:$U$491, E39, Tracker!$I$9:$I$491) -> 31043.459
A40: Britoil 73 | B40: =SUMIF(Tracker!$U$9:$U$491, A40, Tracker!$H$9:$H$491)+SUMIF(Tracker!$U$9:$U$491, A40, Tracker!$I$9:$I$491) -> 32394.726 | C40: Paragon Sentinel | D40: =SUMIF(Tracker!$U$9:$U$491, C40, Tracker!$H$9:$H$491)+SUMIF(Tracker!$U$9:$U$491, C40, Tracker!$I$9:$I$491) -> 10971.685 | E40: BOS Precious | F40: =SUMIF(Tracker!$U$9:$U$491, E40, Tracker!$H$9:$H$491)+SUMIF(Tracker!$U$9:$U$491, E40, Tracker!$I$9:$I$491) -> 28972.471
A41: Britoil 74 | B41: =SUMIF(Tracker!$U$9:$U$491, A41, Tracker!$H$9:$H$491)+SUMIF(Tracker!$U$9:$U$491, A41, Tracker!$I$9:$I$491) -> 27514.751 | C41: Mashhor Princess | D41: =SUMIF(Tracker!$U$9:$U$491, C41, Tracker!$H$9:$H$491)+SUMIF(Tracker!$U$9:$U$491, C41, Tracker!$I$9:$I$491) -> 10543.104 | E41: BOS Prelude | F41: =SUMIF(Tracker!$U$9:$U$491, E41, Tracker!$H$9:$H$491)+SUMIF(Tracker!$U$9:$U$491, E41, Tracker!$I$9:$I$491) -> 13186.189
A42: Britoil 80 | B42: =SUMIF(Tracker!$U$9:$U$491, A42, Tracker!$H$9:$H$491)+SUMIF(Tracker!$U$9:$U$491, A42, Tracker!$I$9:$I$491) -> 25029.157 | C42: Britoil Dominance | D42: =SUMIF(Tracker!$U$9:$U$491, C42, Tracker!$H$9:$H$491)+SUMIF(Tracker!$U$9:$U$491, C42, Tracker!$I$9:$I$491) -> 0 | E42: BOS Prime | F42: =SUMIF(Tracker!$U$9:$U$491, E42, Tracker!$H$9:$H$491)+SUMIF(Tracker!$U$9:$U$491, E42, Tracker!$I$9:$I$491) -> 46400
... A46: Britoil 121 | B46: =SUMIF(Tracker!$U$9:$U$491, A46, Tracker!$H$9:$H$491)+SUMIF(Tracker!$U$9:$U$491, A46, Tracker!$I$9:$I$491) -> 10660 | C46: MWV Falgout | D46: =SUMIF(Tracker!$U$9:$U$491, C46, Tracker!$H$9:$H$491)+SUMIF(Tracker!$U$9:$U$491, C46, Tracker!$I$9:$I$491) -> 0 | E46: BOS Purpose | F46: =SUMIF(Tracker!$U$9:$U$491, E46, Tracker!$H$9:$H$491)+SUMIF(Tracker!$U$9:$U$491, E46, Tracker!$I$9:$I$491) -> 20648.747
...

Sheet Sheet1
A1: =Summary!C21 -> 1670508.1 | B1: =Summary!C22 -> 7055.9398 | C1: =Summary!C23 -> 15 | D1: =Summary!J4 -> 0.93055556 | E1: =Summary!J3 -> 0.64709378 | F1: =Tracker!AE115 -> 14571594 | G1: =Summary!J5 -> 0.073772554

Sheet Sheet2
A1: =Summary!A99 -> Britoil Defiance | B1: =Summary!B99 -> 79887.582 | C1: =Summary!C99 -> 385.15186 | D1: BOS ITALY | E1: =Summary!F25 -> 477830.55 | F1: =E1/23 -> 20775.241 | G1: =Summary!A3 -> MGPS | H1: =Summary!C3 -> 48 | I1: =Summary!D3 -> 1 | J1: =Summary!E3 -> 67 | K1: =Summary!F3 -> 0.73134328 | L1: 1 | M1: 1 | N1: 1 | O1: 1 | P1: 1 | Q1: 1
A2: =Summary!A100 -> Britoil 81 | B2: =Summary!B100 -> 61944.305 | C2: =Summary!C100 -> 285.72097 | D2: BOS SG | E2: =Summary!D25 -> 393234.93 | F2: =E2/16 -> 24577.183 | G2: =Summary!A4 -> EFMS | H2: =Summary!C4 -> 17 | I2: =Summary!D4 -> 1 | J2: =Summary!E4 -> 70 | K2: =Summary!F4 -> 0.25714286
A3: =Summary!A101 -> BOS Pride | B3: =Summary!B101 -> 48229.699 | C3: =Summary!C101 -> 195.43314 | D3: BOS DUBAI | E3: =Summary!B25 -> 694442.62 | F3: =E3/28 -> 24801.522 | G3: =Summary!A5 -> IWTM Filter | H3: =Summary!C5 -> 29 | I3: =Summary!D5 -> 13 | J3: =Summary!E5 -> 44 | K3: =Summary!F5 -> 0.95454545
A4: =Summary!A102 -> BOS Champion | B4: =Summary!B102 -> 47544.567 | C4: =Summary!C102 -> 232.15121 | G4: =Summary!A7 -> CMCE LP | H4: =Summary!C7 -> 12 | I4: =Summary!D7 -> 1 | J4: =Summary!E7 -> 45 | K4: =Summary!F7 -> 0.28888889
A5: =Summary!A103 -> Britoil Journey | B5: =Summary!B103 -> 47000 | C5: =Summary!C103 -> 242 | G5: =Summary!A8 -> LED lights | H5: =Summary!C8 -> 26 | I5: =Summary!D8 -> 2 | J5: =Summary!E8 -> 70 | K5: =Summary!F8 -> 0.4
A6: =Summary!A104 -> BOS Prince | B6: =Summary!B104 -> 46400 | C6: =Summary!C104 -> 179 | G6: =Summary!A9 -> Chlorinator | H6: =Summary!C9 -> 1 | I6: =Summary!D9 -> 1 | J6: =Summary!E9 -> 2 | K6: =Summary!F9 -> 1
A7: =Summary!A105 -> BOS Prime | B7: =Summary!B105 -> 46400 | C7: =Summary!C105 -> 179 | G7: =Summary!A10 -> Deva Paint | H7: =Summary!C10 -> 1 | I7: =Summary!D10 -> 0 | J7: =Summary!E10 -> 72 | K7: =Summary!F10 -> 0.013888889
A8: =Summary!A106 -> Britoil 72 | B8: =Summary!B106 -> 44842.341 | C8: =Summary!C106 -> 249.46774 | G8: =Summary!A11 -> AI CCTV | H8: =Summary!C11 -> 5 | I8: =Summary!D11 -> 0 | J8: =Summary!E11 -> 10 | K8: =Summary!F11 -> 0.5
A9: =Summary!A107 -> Britoil 41 | B9: =Summary!B107 -> 44460 | C9: =Summary!C107 -> 204.1 | G9: =Summary!A13 -> Nautilus Log | H9: =Summary!C13 -> 70 | I9: =Summary!D13 -> 0 | J9: =Summary!E13 -> 72 | K9: =Summary!F13 -> 0.97222222
A10: =Summary!A108 -> Britoil Justice | B10: =Summary!B108 -> 42400 | C10: =Summary!C108 -> 165 | G10: =Summary!A14 -> RE Conversion | H10: =Summary!C14 -> 1 | I10: =Summary!D14 -> 0 | J10: =Summary!E14 -> 1 | K10: =Summary!F14 -> 1
A11: =Summary!A109 -> BOS Principle | B11: =Summary!B109 -> 38900 | C11: =Summary!C109 -> 165 | G11: =Summary!A16 -> Shore Generator | H11: =Summary!C16 -> 2 | I11: =Summary!D16 -> 0 | J11: =Summary!E16 -> 8 | K11: =Summary!F16 -> 0.25
A12: =Summary!A110 -> BOS Prudence | B12: =Summary!B110 -> 36677.455 | C12: =Summary!C110 -> 155.57275 | G12: =Summary!A17 -> IOW Separator | H12: =Summary!C17 -> 0 | I12: =Summary!D17 -> 1 | J12: =Summary!E17 -> 1 | K12: =Summary!F17 -> 1
A13: =Summary!A111 -> Britoil Discovery | B13: =Summary!B111 -> 34700 | C13: =Summary!C111 -> 157
A14: =Summary!A112 -> BOS Challenge | B14: =Summary!B112 -> 34358.379 | C14: =Summary!C112 -> 172.7205
A15: =Summary!A113 -> Britoil Diamond | B15: =Summary!B113 -> 33545.998 | C15: =Summary!C113 -> 153.99771
A16: =Summary!A114 -> Britoil 73 | B16: =Summary!B114 -> 32394.726 | C16: =Summary!C114 -> 163.01192
A17: =Summary!A115 -> BOS Ares | B17: =Summary!B115 -> 32004.676 | C17: =Summary!C115 -> 178.049
A18: =Summary!A116 -> BOS Patience | B18: =Summary!B116 -> 31043.459 | C18: =Summary!C116 -> 174.54624
A19: =Summary!A117 -> BOS Patriot | B19: =Summary!B117 -> 31043.459 | C19: =Summary!C117 -> 174.54624
A20: =Summary!A118 -> BOS Precious | B20: =Summary!B118 -> 28972.471 | C20: =Summary!C118 -> 145.79096
A21: =Summary!A119 -> Britoil 60 | B21: =Summary!B119 -> 28470 | C21: =Summary!C119 -> 93.6
A22: =Summary!A120 -> Britoil 61 | B22: =Summary!B120 -> 28470 | C22: =Summary!C120 -> 93.6
A23: =Summary!A121 -> Britoil 74 | B23: =Summary!B121 -> 27514.751 | C23: =Summary!C121 -> 154.70558
A24: =Summary!A122 -> Britoil 70 | B24: =Summary!B122 -> 27317.748 | C24: =Summary!C122 -> 153.59791
... A69: =Summary!A167 -> Britoil Dominance | B69: =Summary!B167 -> 0 | C69: =Summary!C167 -> 0

Sheet Sheet3
A1: BOS ITALY | B1: =Sheet2!E1 -> 477830.55 | C1: =Sheet2!F1 -> 20775.241
A2: BOS SG | B2: =Sheet2!E2 -> 393234.93 | C2: =Sheet2!F2 -> 24577.183
A3: BOS DUBAI | B3: =Sheet2!E3 -> 694442.62 | C3: =Sheet2!F3 -> 24801.522

Sheet Sheet4
A1: =Sheet2!G1 -> MGPS | B1: =Sheet2!H1 -> 48 | C1: =Sheet2!I1 -> 1 | D1: =Sheet2!J1 -> 67 | E1: =Summary!N3 -> 681600
A2: =Sheet2!G2 -> EFMS | B2: =Sheet2!H2 -> 17 | C2: =Sheet2!I2 -> 1 | D2: =Sheet2!J2 -> 70 | E2: =Summary!N4 -> 289000
A3: =Sheet2!G3 -> IWTM Filter | B3: =Sheet2!H3 -> 29 | C3: =Sheet2!I3 -> 13 | D3: =Sheet2!J3 -> 44 | E3: =Summary!N5 -> 223300
A4: =Sheet2!G4 -> CMCE LP | B4: =Sheet2!H4 -> 12 | C4: =Sheet2!I4 -> 1 | D4: =Sheet2!J4 -> 45 | E4: =Summary!N7 -> 90000
A5: =Sheet2!G5 -> LED lights | B5: =Sheet2!H5 -> 26 | C5: =Sheet2!I5 -> 2 | D5: =Sheet2!J5 -> 70 | E5: =Summary!N8 -> 319800
A6: =Sheet2!G6 -> Chlorinator | B6: =Sheet2!H6 -> 1 | C6: =Sheet2!I6 -> 1 | D6: =Sheet2!J6 -> 2 | E6: =Summary!N9 -> 12300
A7: =Sheet2!G7 -> Deva Paint | B7: =Sheet2!H7 -> 1 | C7: =Sheet2!I7 -> 0 | D7: =Sheet2!J7 -> 72 | E7: =Summary!N11 -> 20000
A8: =Sheet2!G8 -> AI CCTV | B8: =Sheet2!H8 -> 5 | C8: =Sheet2!I8 -> 0 | D8: =Sheet2!J8 -> 10 | E8: =Summary!N13 -> 210000
A9: =Sheet2!G9 -> Nautilus Log | B9: =Sheet2!H9 -> 70 | C9: =Sheet2!I9 -> 0 | D9: =Sheet2!J9 -> 72 | E9: =Summary!N14 -> 1500
A10: =Sheet2!G10 -> RE Conversion | B10: =Sheet2!H10 -> 1 | C10: =Sheet2!I10 -> 0 | D10: =Sheet2!J10 -> 1 | E10: =Summary!N17 -> 0
A11: =Sheet2!G11 -> Shore Generator | B11: =Sheet2!H11 -> 2 | C11: =Sheet2!I11 -> 0 | D11: =Sheet2!J11 -> 8 | E11: =Summary!N18 -> 0
A12: =Sheet2!G12 -> IOW Separator | B12: =Sheet2!H12 -> 0 | C12: =Sheet2!I12 -> 1 | D12: =Sheet2!J12 -> 1 | E12: =Summary!N19 -> 0
